2024-08-29 18:18:46,375 ERROR: Exception on /user/Zhenya [GET] [in /home/gaia/PycharmProjects/microblog/.venv/lib/python3.12/site-packages/flask/app.py:838]
Traceback (most recent call last):
  File "/home/gaia/PycharmProjects/microblog/.venv/lib/python3.12/site-packages/flask/app.py", line 1473, in wsgi_app
    response = self.full_dispatch_request()
               ^^^^^^^^^^^^^^^^^^^^^^^^^^^^
  File "/home/gaia/PycharmProjects/microblog/.venv/lib/python3.12/site-packages/flask/app.py", line 882, in full_dispatch_request
    rv = self.handle_user_exception(e)
         ^^^^^^^^^^^^^^^^^^^^^^^^^^^^^
  File "/home/gaia/PycharmProjects/microblog/.venv/lib/python3.12/site-packages/flask/app.py", line 880, in full_dispatch_request
    rv = self.dispatch_request()
         ^^^^^^^^^^^^^^^^^^^^^^^
  File "/home/gaia/PycharmProjects/microblog/.venv/lib/python3.12/site-packages/flask/app.py", line 865, in dispatch_request
    return self.ensure_sync(self.view_functions[rule.endpoint])(**view_args)  # type: ignore[no-any-return]
           ^^^^^^^^^^^^^^^^^^^^^^^^^^^^^^^^^^^^^^^^^^^^^^^^^^^^^^^^^^^^^^^^^
  File "/home/gaia/PycharmProjects/microblog/.venv/lib/python3.12/site-packages/flask_login/utils.py", line 290, in decorated_view
    return current_app.ensure_sync(func)(*args, **kwargs)
           ^^^^^^^^^^^^^^^^^^^^^^^^^^^^^^^^^^^^^^^^^^^^^^
  File "/home/gaia/PycharmProjects/microblog/app/routes.py", line 138, in user
    return render_template('user.html', user=user, posts=posts,form=form)
           ^^^^^^^^^^^^^^^^^^^^^^^^^^^^^^^^^^^^^^^^^^^^^^^^^^^^^^^^^^^^^^
  File "/home/gaia/PycharmProjects/microblog/.venv/lib/python3.12/site-packages/flask/templating.py", line 150, in render_template
    return _render(app, template, context)
           ^^^^^^^^^^^^^^^^^^^^^^^^^^^^^^^
  File "/home/gaia/PycharmProjects/microblog/.venv/lib/python3.12/site-packages/flask/templating.py", line 131, in _render
    rv = template.render(context)
         ^^^^^^^^^^^^^^^^^^^^^^^^
  File "/home/gaia/PycharmProjects/microblog/.venv/lib/python3.12/site-packages/jinja2/environment.py", line 1304, in render
    self.environment.handle_exception()
  File "/home/gaia/PycharmProjects/microblog/.venv/lib/python3.12/site-packages/jinja2/environment.py", line 939, in handle_exception
    raise rewrite_traceback_stack(source=source)
  File "/home/gaia/PycharmProjects/microblog/app/templates/user.html", line 1, in top-level template code
    {% extends "base.html" %}
  File "/home/gaia/PycharmProjects/microblog/app/templates/base.html", line 58, in top-level template code
    {% block content %}{% endblock %}
    ^^^^^^^^^^^^^^^^^^^^^^^^^
  File "/home/gaia/PycharmProjects/microblog/app/templates/user.html", line 35, in block 'content'
    {% include '_post.html' %}
    ^^^^^^^^^^^^^^^^^^^^^^^^^
  File "/home/gaia/PycharmProjects/microblog/app/templates/_post.html", line 14, in top-level template code
    {{ _('%(username)s said %(when)s',
    ^^^^^^^^^^^^^^^^^^^^^^^^^
  File "/home/gaia/PycharmProjects/microblog/.venv/lib/python3.12/site-packages/flask_moment/__init__.py", line 237, in fromNow
    return self._render("fromNow", no_suffix=int(no_suffix),
           ^^^^^^^^^^^^^^^^^^^^^^^^^^^^^^^^^^^^^^^^^^^^^^^^^
  File "/home/gaia/PycharmProjects/microblog/.venv/lib/python3.12/site-packages/flask_moment/__init__.py", line 194, in _render
    t = self._timestamp_as_iso_8601(self.timestamp)
        ^^^^^^^^^^^^^^^^^^^^^^^^^^^^^^^^^^^^^^^^^^^
  File "/home/gaia/PycharmProjects/microblog/.venv/lib/python3.12/site-packages/flask_moment/__init__.py", line 190, in _timestamp_as_iso_8601
    return timestamp.strftime('%Y-%m-%dT%H:%M:%S' + tz)
           ^^^^^^^^^^^^^^^^^^
jinja2.exceptions.UndefinedError: 'dict object' has no attribute 'timestamp'
2024-08-30 13:11:07,177 INFO: Microblog startup [in /home/gaia/PycharmProjects/microblog/app/__init__.py:57]
2024-08-30 13:11:12,733 ERROR: Exception on /index [GET] [in /home/gaia/PycharmProjects/microblog/.venv/lib/python3.12/site-packages/flask/app.py:838]
Traceback (most recent call last):
  File "/home/gaia/PycharmProjects/microblog/.venv/lib/python3.12/site-packages/flask/app.py", line 1473, in wsgi_app
    response = self.full_dispatch_request()
               ^^^^^^^^^^^^^^^^^^^^^^^^^^^^
  File "/home/gaia/PycharmProjects/microblog/.venv/lib/python3.12/site-packages/flask/app.py", line 882, in full_dispatch_request
    rv = self.handle_user_exception(e)
         ^^^^^^^^^^^^^^^^^^^^^^^^^^^^^
  File "/home/gaia/PycharmProjects/microblog/.venv/lib/python3.12/site-packages/flask/app.py", line 878, in full_dispatch_request
    rv = self.preprocess_request()
         ^^^^^^^^^^^^^^^^^^^^^^^^^
  File "/home/gaia/PycharmProjects/microblog/.venv/lib/python3.12/site-packages/flask/app.py", line 1253, in preprocess_request
    rv = self.ensure_sync(before_func)()
         ^^^^^^^^^^^^^^^^^^^^^^^^^^^^^^^
  File "/home/gaia/PycharmProjects/microblog/app/routes.py", line 22, in before_request
    g.locale = str(get_locale())
    ^
NameError: name 'g' is not defined
2024-08-30 13:11:13,041 ERROR: Exception on /favicon.ico [GET] [in /home/gaia/PycharmProjects/microblog/.venv/lib/python3.12/site-packages/flask/app.py:838]
Traceback (most recent call last):
  File "/home/gaia/PycharmProjects/microblog/.venv/lib/python3.12/site-packages/flask/app.py", line 1473, in wsgi_app
    response = self.full_dispatch_request()
               ^^^^^^^^^^^^^^^^^^^^^^^^^^^^
  File "/home/gaia/PycharmProjects/microblog/.venv/lib/python3.12/site-packages/flask/app.py", line 882, in full_dispatch_request
    rv = self.handle_user_exception(e)
         ^^^^^^^^^^^^^^^^^^^^^^^^^^^^^
  File "/home/gaia/PycharmProjects/microblog/.venv/lib/python3.12/site-packages/flask/app.py", line 878, in full_dispatch_request
    rv = self.preprocess_request()
         ^^^^^^^^^^^^^^^^^^^^^^^^^
  File "/home/gaia/PycharmProjects/microblog/.venv/lib/python3.12/site-packages/flask/app.py", line 1253, in preprocess_request
    rv = self.ensure_sync(before_func)()
         ^^^^^^^^^^^^^^^^^^^^^^^^^^^^^^^
  File "/home/gaia/PycharmProjects/microblog/app/routes.py", line 22, in before_request
    g.locale = str(get_locale())
    ^
NameError: name 'g' is not defined
2024-08-30 13:11:14,720 ERROR: Exception on /index [GET] [in /home/gaia/PycharmProjects/microblog/.venv/lib/python3.12/site-packages/flask/app.py:838]
Traceback (most recent call last):
  File "/home/gaia/PycharmProjects/microblog/.venv/lib/python3.12/site-packages/flask/app.py", line 1473, in wsgi_app
    response = self.full_dispatch_request()
               ^^^^^^^^^^^^^^^^^^^^^^^^^^^^
  File "/home/gaia/PycharmProjects/microblog/.venv/lib/python3.12/site-packages/flask/app.py", line 882, in full_dispatch_request
    rv = self.handle_user_exception(e)
         ^^^^^^^^^^^^^^^^^^^^^^^^^^^^^
  File "/home/gaia/PycharmProjects/microblog/.venv/lib/python3.12/site-packages/flask/app.py", line 878, in full_dispatch_request
    rv = self.preprocess_request()
         ^^^^^^^^^^^^^^^^^^^^^^^^^
  File "/home/gaia/PycharmProjects/microblog/.venv/lib/python3.12/site-packages/flask/app.py", line 1253, in preprocess_request
    rv = self.ensure_sync(before_func)()
         ^^^^^^^^^^^^^^^^^^^^^^^^^^^^^^^
  File "/home/gaia/PycharmProjects/microblog/app/routes.py", line 22, in before_request
    g.locale = str(get_locale())
    ^
NameError: name 'g' is not defined
2024-08-30 13:11:16,246 ERROR: Exception on /explore [GET] [in /home/gaia/PycharmProjects/microblog/.venv/lib/python3.12/site-packages/flask/app.py:838]
Traceback (most recent call last):
  File "/home/gaia/PycharmProjects/microblog/.venv/lib/python3.12/site-packages/flask/app.py", line 1473, in wsgi_app
    response = self.full_dispatch_request()
               ^^^^^^^^^^^^^^^^^^^^^^^^^^^^
  File "/home/gaia/PycharmProjects/microblog/.venv/lib/python3.12/site-packages/flask/app.py", line 882, in full_dispatch_request
    rv = self.handle_user_exception(e)
         ^^^^^^^^^^^^^^^^^^^^^^^^^^^^^
  File "/home/gaia/PycharmProjects/microblog/.venv/lib/python3.12/site-packages/flask/app.py", line 878, in full_dispatch_request
    rv = self.preprocess_request()
         ^^^^^^^^^^^^^^^^^^^^^^^^^
  File "/home/gaia/PycharmProjects/microblog/.venv/lib/python3.12/site-packages/flask/app.py", line 1253, in preprocess_request
    rv = self.ensure_sync(before_func)()
         ^^^^^^^^^^^^^^^^^^^^^^^^^^^^^^^
  File "/home/gaia/PycharmProjects/microblog/app/routes.py", line 22, in before_request
    g.locale = str(get_locale())
    ^
NameError: name 'g' is not defined
2024-08-30 13:11:18,094 ERROR: Exception on /explore [GET] [in /home/gaia/PycharmProjects/microblog/.venv/lib/python3.12/site-packages/flask/app.py:838]
Traceback (most recent call last):
  File "/home/gaia/PycharmProjects/microblog/.venv/lib/python3.12/site-packages/flask/app.py", line 1473, in wsgi_app
    response = self.full_dispatch_request()
               ^^^^^^^^^^^^^^^^^^^^^^^^^^^^
  File "/home/gaia/PycharmProjects/microblog/.venv/lib/python3.12/site-packages/flask/app.py", line 882, in full_dispatch_request
    rv = self.handle_user_exception(e)
         ^^^^^^^^^^^^^^^^^^^^^^^^^^^^^
  File "/home/gaia/PycharmProjects/microblog/.venv/lib/python3.12/site-packages/flask/app.py", line 878, in full_dispatch_request
    rv = self.preprocess_request()
         ^^^^^^^^^^^^^^^^^^^^^^^^^
  File "/home/gaia/PycharmProjects/microblog/.venv/lib/python3.12/site-packages/flask/app.py", line 1253, in preprocess_request
    rv = self.ensure_sync(before_func)()
         ^^^^^^^^^^^^^^^^^^^^^^^^^^^^^^^
  File "/home/gaia/PycharmProjects/microblog/app/routes.py", line 22, in before_request
    g.locale = str(get_locale())
    ^
NameError: name 'g' is not defined
